<?xml version="1.0" ?>
<testsuite errors="3" failures="0" name="acc_group.create_group_test-20180424175111" tests="3" time="1474.406">
	<testcase classname="acc_group.create_group_test" name="test_01_nav_acc_group" time="31.137">
		<error message="Test fail: Please check the traceback" type="AssertionError">
<![CDATA[Traceback (most recent call last):
  File "/home/rishabh/docs-screenshot/webui/tests/acc_group.py", line 73, in test_01_nav_acc_group
    self.assertEqual("Just for fail", str(Exception), msg="Test fail: Please check the traceback")
AssertionError: Test fail: Please check the traceback
]]>		</error>
	</testcase>
	<testcase classname="acc_group.create_group_test" name="test_02_create_newgroup" time="1412.139">
		<error message="Test fail: Please check the traceback" type="AssertionError">
<![CDATA[Traceback (most recent call last):
  File "/home/rishabh/docs-screenshot/webui/tests/acc_group.py", line 98, in test_02_create_newgroup
    self.assertEqual("Just for fail", str(Exception), msg="Test fail: Please check the traceback")
AssertionError: Test fail: Please check the traceback
]]>		</error>
	</testcase>
	<testcase classname="acc_group.create_group_test" name="test_03_close_navAccount" time="31.131">
		<error message="Test fail: Please check the traceback" type="AssertionError">
<![CDATA[Traceback (most recent call last):
  File "/home/rishabh/docs-screenshot/webui/tests/acc_group.py", line 112, in test_03_close_navAccount
    self.assertEqual("Just for fail", str(Exception), msg="Test fail: Please check the traceback")
AssertionError: Test fail: Please check the traceback
]]>		</error>
	</testcase>
	<system-out>
<![CDATA[ navigating to the group submenu
Taking screenshot for acc_group-test_01_nav_acc_group
  File "/home/rishabh/docs-screenshot/webui/tests/acc_group.py", line 54, in test_01_nav_acc_group
    driver.find_element_by_xpath(xpaths['navAccount']).click()

  File "/usr/local/lib/python2.7/dist-packages/selenium/webdriver/remote/webdriver.py", line 365, in find_element_by_xpath
    return self.find_element(by=By.XPATH, value=xpath)

  File "/usr/local/lib/python2.7/dist-packages/selenium/webdriver/remote/webdriver.py", line 855, in find_element
    'value': value})['value']

  File "/usr/local/lib/python2.7/dist-packages/selenium/webdriver/remote/webdriver.py", line 308, in execute
    self.error_handler.check_response(response)

  File "/usr/local/lib/python2.7/dist-packages/selenium/webdriver/remote/errorhandler.py", line 194, in check_response
    raise exception_class(message, screen, stacktrace)

NoSuchElementException: Message: Unable to locate element: //*[@id="nav-1"]/div/a[1]


 creating a new group without root access
Taking screenshot for acc_group-test_02_create_newgroup
  File "/home/rishabh/docs-screenshot/webui/tests/acc_group.py", line 83, in test_02_create_newgroup
    hover_element = driver.find_element_by_xpath(xpaths['fabTrigger'])

  File "/usr/local/lib/python2.7/dist-packages/selenium/webdriver/remote/webdriver.py", line 365, in find_element_by_xpath
    return self.find_element(by=By.XPATH, value=xpath)

  File "/usr/local/lib/python2.7/dist-packages/selenium/webdriver/remote/webdriver.py", line 855, in find_element
    'value': value})['value']

  File "/usr/local/lib/python2.7/dist-packages/selenium/webdriver/remote/webdriver.py", line 308, in execute
    self.error_handler.check_response(response)

  File "/usr/local/lib/python2.7/dist-packages/selenium/webdriver/remote/errorhandler.py", line 194, in check_response
    raise exception_class(message, screen, stacktrace)

NoSuchElementException: Message: Unable to locate element: //*[@id="myFab"]/div/smd-fab-trigger/button


 closing account menu
Taking screenshot for acc_group-test_03_close_navAccount
  File "/home/rishabh/docs-screenshot/webui/tests/acc_group.py", line 103, in test_03_close_navAccount
    driver.find_element_by_xpath(xpaths['navAccount']).click()

  File "/usr/local/lib/python2.7/dist-packages/selenium/webdriver/remote/webdriver.py", line 365, in find_element_by_xpath
    return self.find_element(by=By.XPATH, value=xpath)

  File "/usr/local/lib/python2.7/dist-packages/selenium/webdriver/remote/webdriver.py", line 855, in find_element
    'value': value})['value']

  File "/usr/local/lib/python2.7/dist-packages/selenium/webdriver/remote/webdriver.py", line 308, in execute
    self.error_handler.check_response(response)

  File "/usr/local/lib/python2.7/dist-packages/selenium/webdriver/remote/errorhandler.py", line 194, in check_response
    raise exception_class(message, screen, stacktrace)

NoSuchElementException: Message: Unable to locate element: //*[@id="nav-1"]/div/a[1]


]]>	</system-out>
	<system-err>
<![CDATA[]]>	</system-err>
</testsuite>
